Workbook

Sheet Parâmetros
A1: PARÂMETROS CONFIGURÁVEIS — edite as células em amarelo
A3: Planos e Preços (R$)
A4: Plano | B4: Preço Mensal | C4: Preço Trimestral | D4: Preço Anual
A5: Core | B5: 9.99 | C5: 27 | D5: 99
A6: Standard | B6: 14.99 | C6: 40 | D6: 149
A7: Ultimate | B7: 21.99 | C7: 59 | D7: 219
A9: Add-ons Opcionais (R$ por assinatura)
A10: Add-on | B10: Preço
A11: EA Play | B11: 4.99
A12: Minecraft Pass | B12: 3.99
A13: Call of Duty Pass | B13: 6.99
A15: Metas e Premissas de Negócio
A17: Meta de Receita Anual (R$) | B17: 6000000
A18: Meta de Assinantes | B18: 250000
A19: Taxa de Conversão Alvo | B19: 0.18
A20: CAC — Custo de Aquisição (R$/un.) | B20: 12
A21: Margem de Lucro Alvo | B21: 0.35
A22: Desconto Campanha Promoção | B22: 0.1
A23: Crescimento Mensal Esperado | B23: 0.05
A24: Câmbio USD → BRL (R$) | B24: 5.4

Sheet Base de Dados
A1: ID | B1: Data | C1: Plano | D1: Ciclo | E1: Região | F1: Canal | G1: EA Play | H1: Minecraft | I1: CoD | J1: Tipo | K1: Qtd | L1: Preço Unit. | M1: Valor EA Play | N1: Valor Minecraft | O1: Valor CoD | P1: Receita (R$) | Q1: Custo (R$) | R1: Lucro (R$)
A2: 1 | B2: 45946 | C2: Core | D2: Trimestral | E2: Sudeste | F2: Loja Online | G2: Sim | H2: Não | I2: Não | J2: Renovação | K2: 3 | L2: =IFERROR(VLOOKUP(C2,Parâmetros!$A$5:$D$7,IF(D2="Mensal",2,IF(D2="Trimestral",3,4)),0),0) -> 27 | M2: =IF(G2="Sim",VLOOKUP("EA Play",Parâmetros!$A$11:$B$13,2,0),0)*K2 -> 14.97 | N2: =IF(H2="Sim",VLOOKUP("Minecraft Pass",Parâmetros!$A$11:$B$13,2,0),0)*K2 -> 0 | O2: =IF(I2="Sim",VLOOKUP("Call of Duty Pass",Parâmetros!$A$11:$B$13,2,0),0)*K2 -> 0 | P2: =(L2*K2+M2+N2+O2)*IF(F2="Promoção",1-Parâmetros!$B$22,1) -> 95.97 | Q2: =Parâmetros!$B$20*K2 -> 36 | R2: =P2-Q2 -> 59.97
A3: 2 | B3: 45322 | C3: Core | D3: Mensal | E3: Sul | F3: Loja Física | G3: Não | H3: Não | I3: Não | J3: Novo | K3: 18 | L3: =IFERROR(VLOOKUP(C3,Parâmetros!$A$5:$D$7,IF(D3="Mensal",2,IF(D3="Trimestral",3,4)),0),0) -> 9.99 | M3: =IF(G3="Sim",VLOOKUP("EA Play",Parâmetros!$A$11:$B$13,2,0),0)*K3 -> 0 | N3: =IF(H3="Sim",VLOOKUP("Minecraft Pass",Parâmetros!$A$11:$B$13,2,0),0)*K3 -> 0 | O3: =IF(I3="Sim",VLOOKUP("Call of Duty Pass",Parâmetros!$A$11:$B$13,2,0),0)*K3 -> 0 | P3: =(L3*K3+M3+N3+O3)*IF(F3="Promoção",1-Parâmetros!$B$22,1) -> 179.82 | Q3: =Parâmetros!$B$20*K3 -> 216 | R3: =P3-Q3 -> -36.18
A4: 3 | B4: 45298 | C4: Ultimate | D4: Mensal | E4: Sul | F4: Loja Online | G4: Sim | H4: Não | I4: Sim | J4: Novo | K4: 23 | L4: =IFERROR(VLOOKUP(C4,Parâmetros!$A$5:$D$7,IF(D4="Mensal",2,IF(D4="Trimestral",3,4)),0),0) -> 21.99 | M4: =IF(G4="Sim",VLOOKUP("EA Play",Parâmetros!$A$11:$B$13,2,0),0)*K4 -> 114.77 | N4: =IF(H4="Sim",VLOOKUP("Minecraft Pass",Parâmetros!$A$11:$B$13,2,0),0)*K4 -> 0 | O4: =IF(I4="Sim",VLOOKUP("Call of Duty Pass",Parâmetros!$A$11:$B$13,2,0),0)*K4 -> 160.77 | P4: =(L4*K4+M4+N4+O4)*IF(F4="Promoção",1-Parâmetros!$B$22,1) -> 781.31 | Q4: =Parâmetros!$B$20*K4 -> 276 | R4: =P4-Q4 -> 505.31
A5: 4 | B5: 45644 | C5: Standard | D5: Anual | E5: Nordeste | F5: Loja Física | G5: Não | H5: Sim | I5: Não | J5: Renovação | K5: 24 | L5: =IFERROR(VLOOKUP(C5,Parâmetros!$A$5:$D$7,IF(D5="Mensal",2,IF(D5="Trimestral",3,4)),0),0) -> 149 | M5: =IF(G5="Sim",VLOOKUP("EA Play",Parâmetros!$A$11:$B$13,2,0),0)*K5 -> 0 | N5: =IF(H5="Sim",VLOOKUP("Minecraft Pass",Parâmetros!$A$11:$B$13,2,0),0)*K5 -> 95.76 | O5: =IF(I5="Sim",VLOOKUP("Call of Duty Pass",Parâmetros!$A$11:$B$13,2,0),0)*K5 -> 0 | P5: =(L5*K5+M5+N5+O5)*IF(F5="Promoção",1-Parâmetros!$B$22,1) -> 3671.76 | Q5: =Parâmetros!$B$20*K5 -> 288 | R5: =P5-Q5 -> 3383.76
A6: 5 | B6: 45883 | C6: Core | D6: Mensal | E6: Nordeste | F6: Parceiro | G6: Não | H6: Não | I6: Não | J6: Novo | K6: 30 | L6: =IFERROR(VLOOKUP(C6,Parâmetros!$A$5:$D$7,IF(D6="Mensal",2,IF(D6="Trimestral",3,4)),0),0) -> 9.99 | M6: =IF(G6="Sim",VLOOKUP("EA Play",Parâmetros!$A$11:$B$13,2,0),0)*K6 -> 0 | N6: =IF(H6="Sim",VLOOKUP("Minecraft Pass",Parâmetros!$A$11:$B$13,2,0),0)*K6 -> 0 | O6: =IF(I6="Sim",VLOOKUP("Call of Duty Pass",Parâmetros!$A$11:$B$13,2,0),0)*K6 -> 0 | P6: =(L6*K6+M6+N6+O6)*IF(F6="Promoção",1-Parâmetros!$B$22,1) -> 299.7 | Q6: =Parâmetros!$B$20*K6 -> 360 | R6: =P6-Q6 -> -60.3
A7: 6 | B7: 45942 | C7: Ultimate | D7: Mensal | E7: Sudeste | F7: Parceiro | G7: Não | H7: Não | I7: Sim | J7: Renovação | K7: 35 | L7: =IFERROR(VLOOKUP(C7,Parâmetros!$A$5:$D$7,IF(D7="Mensal",2,IF(D7="Trimestral",3,4)),0),0) -> 21.99 | M7: =IF(G7="Sim",VLOOKUP("EA Play",Parâmetros!$A$11:$B$13,2,0),0)*K7 -> 0 | N7: =IF(H7="Sim",VLOOKUP("Minecraft Pass",Parâmetros!$A$11:$B$13,2,0),0)*K7 -> 0 | O7: =IF(I7="Sim",VLOOKUP("Call of Duty Pass",Parâmetros!$A$11:$B$13,2,0),0)*K7 -> 244.65 | P7: =(L7*K7+M7+N7+O7)*IF(F7="Promoção",1-Parâmetros!$B$22,1) -> 1014.3 | Q7: =Parâmetros!$B$20*K7 -> 420 | R7: =P7-Q7 -> 594.3
A8: 7 | B8: 45542 | C8: Core | D8: Mensal | E8: Norte | F8: Parceiro | G8: Não | H8: Não | I8: Não | J8: Renovação | K8: 15 | L8: =IFERROR(VLOOKUP(C8,Parâmetros!$A$5:$D$7,IF(D8="Mensal",2,IF(D8="Trimestral",3,4)),0),0) -> 9.99 | M8: =IF(G8="Sim",VLOOKUP("EA Play",Parâmetros!$A$11:$B$13,2,0),0)*K8 -> 0 | N8: =IF(H8="Sim",VLOOKUP("Minecraft Pass",Parâmetros!$A$11:$B$13,2,0),0)*K8 -> 0 | O8: =IF(I8="Sim",VLOOKUP("Call of Duty Pass",Parâmetros!$A$11:$B$13,2,0),0)*K8 -> 0 | P8: =(L8*K8+M8+N8+O8)*IF(F8="Promoção",1-Parâmetros!$B$22,1) -> 149.85 | Q8: =Parâmetros!$B$20*K8 -> 180 | R8: =P8-Q8 -> -30.15
A9: 8 | B9: 45324 | C9: Ultimate | D9: Mensal | E9: Sudeste | F9: Promoção | G9: Não | H9: Não | I9: Sim | J9: Novo | K9: 30 | L9: =IFERROR(VLOOKUP(C9,Parâmetros!$A$5:$D$7,IF(D9="Mensal",2,IF(D9="Trimestral",3,4)),0),0) -> 21.99 | M9: =IF(G9="Sim",VLOOKUP("EA Play",Parâmetros!$A$11:$B$13,2,0),0)*K9 -> 0 | N9: =IF(H9="Sim",VLOOKUP("Minecraft Pass",Parâmetros!$A$11:$B$13,2,0),0)*K9 -> 0 | O9: =IF(I9="Sim",VLOOKUP("Call of Duty Pass",Parâmetros!$A$11:$B$13,2,0),0)*K9 -> 209.7 | P9: =(L9*K9+M9+N9+O9)*IF(F9="Promoção",1-Parâmetros!$B$22,1) -> 782.46 | Q9: =Parâmetros!$B$20*K9 -> 360 | R9: =P9-Q9 -> 422.46
A10: 9 | B10: 45438 | C10: Core | D10: Mensal | E10: Sul | F10: Loja Online | G10: Não | H10: Não | I10: Não | J10: Novo | K10: 9 | L10: =IFERROR(VLOOKUP(C10,Parâmetros!$A$5:$D$7,IF(D10="Mensal",2,IF(D10="Trimestral",3,4)),0),0) -> 9.99 | M10: =IF(G10="Sim",VLOOKUP("EA Play",Parâmetros!$A$11:$B$13,2,0),0)*K10 -> 0 | N10: =IF(H10="Sim",VLOOKUP("Minecraft Pass",Parâmetros!$A$11:$B$13,2,0),0)*K10 -> 0 | O10: =IF(I10="Sim",VLOOKUP("Call of Duty Pass",Parâmetros!$A$11:$B$13,2,0),0)*K10 -> 0 | P10: =(L10*K10+M10+N10+O10)*IF(F10="Promoção",1-Parâmetros!$B$22,1) -> 89.91 | Q10: =Parâmetros!$B$20*K10 -> 108 | R10: =P10-Q10 -> -18.09
A11: 10 | B11: 45813 | C11: Standard | D11: Trimestral | E11: Centro-Oeste | F11: Loja Online | G11: Sim | H11: Não | I11: Não | J11: Novo | K11: 30 | L11: =IFERROR(VLOOKUP(C11,Parâmetros!$A$5:$D$7,IF(D11="Mensal",2,IF(D11="Trimestral",3,4)),0),0) -> 40 | M11: =IF(G11="Sim",VLOOKUP("EA Play",Parâmetros!$A$11:$B$13,2,0),0)*K11 -> 149.7 | N11: =IF(H11="Sim",VLOOKUP("Minecraft Pass",Parâmetros!$A$11:$B$13,2,0),0)*K11 -> 0 | O11: =IF(I11="Sim",VLOOKUP("Call of Duty Pass",Parâmetros!$A$11:$B$13,2,0),0)*K11 -> 0 | P11: =(L11*K11+M11+N11+O11)*IF(F11="Promoção",1-Parâmetros!$B$22,1) -> 1349.7 | Q11: =Parâmetros!$B$20*K11 -> 360 | R11: =P11-Q11 -> 989.7
A12: 11 | B12: 45833 | C12: Core | D12: Trimestral | E12: Norte | F12: Parceiro | G12: Sim | H12: Não | I12: Não | J12: Renovação | K12: 22 | L12: =IFERROR(VLOOKUP(C12,Parâmetros!$A$5:$D$7,IF(D12="Mensal",2,IF(D12="Trimestral",3,4)),0),0) -> 27 | M12: =IF(G12="Sim",VLOOKUP("EA Play",Parâmetros!$A$11:$B$13,2,0),0)*K12 -> 109.78 | N12: =IF(H12="Sim",VLOOKUP("Minecraft Pass",Parâmetros!$A$11:$B$13,2,0),0)*K12 -> 0 | O12: =IF(I12="Sim",VLOOKUP("Call of Duty Pass",Parâmetros!$A$11:$B$13,2,0),0)*K12 -> 0 | P12: =(L12*K12+M12+N12+O12)*IF(F12="Promoção",1-Parâmetros!$B$22,1) -> 703.78 | Q12: =Parâmetros!$B$20*K12 -> 264 | R12: =P12-Q12 -> 439.78
A13: 12 | B13: 45406 | C13: Core | D13: Mensal | E13: Sudeste | F13: Parceiro | G13: Não | H13: Não | I13: Não | J13: Novo | K13: 7 | L13: =IFERROR(VLOOKUP(C13,Parâmetros!$A$5:$D$7,IF(D13="Mensal",2,IF(D13="Trimestral",3,4)),0),0) -> 9.99 | M13: =IF(G13="Sim",VLOOKUP("EA Play",Parâmetros!$A$11:$B$13,2,0),0)*K13 -> 0 | N13: =IF(H13="Sim",VLOOKUP("Minecraft Pass",Parâmetros!$A$11:$B$13,2,0),0)*K13 -> 0 | O13: =IF(I13="Sim",VLOOKUP("Call of Duty Pass",Parâmetros!$A$11:$B$13,2,0),0)*K13 -> 0 | P13: =(L13*K13+M13+N13+O13)*IF(F13="Promoção",1-Parâmetros!$B$22,1) -> 69.93 | Q13: =Parâmetros!$B$20*K13 -> 84 | R13: =P13-Q13 -> -14.07
... A1201: 1200 | B1201: 45876 | C1201: Standard | D1201: Mensal | E1201: Sudeste | F1201: Loja Online | G1201: Sim | H1201: Sim | I1201: Não | J1201: Novo | K1201: 34 | L1201: =IFERROR(VLOOKUP(C1201,Parâmetros!$A$5:$D$7,IF(D1201="Mensal",2,IF(D1201="Trimestral",3,4)),0),0) -> 14.99 | M1201: =IF(G1201="Sim",VLOOKUP("EA Play",Parâmetros!$A$11:$B$13,2,0),0)*K1201 -> 169.66 | N1201: =IF(H1201="Sim",VLOOKUP("Minecraft Pass",Parâmetros!$A$11:$B$13,2,0),0)*K1201 -> 135.66 | O1201: =IF(I1201="Sim",VLOOKUP("Call of Duty Pass",Parâmetros!$A$11:$B$13,2,0),0)*K1201 -> 0 | P1201: =(L1201*K1201+M1201+N1201+O1201)*IF(F1201="Promoção",1-Parâmetros!$B$22,1) -> 814.98 | Q1201: =Parâmetros!$B$20*K1201 -> 408 | R1201: =P1201-Q1201 -> 406.98

Sheet Cálculos
A2: RECEITA POR PLANO
A3: Plano | B3: Receita (R$) | C3: Participação
A4: Core | B4: =SUMIFS('Base de Dados'!$P$2:$P$1201,'Base de Dados'!$C$2:$C$1201,A4) -> 338073.3 | C4: =IF($B$7=0,0,B4/$B$7) -> 0.2925454
A5: Standard | B5: =SUMIFS('Base de Dados'!$P$2:$P$1201,'Base de Dados'!$C$2:$C$1201,A5) -> 437443.69 | C5: =IF($B$7=0,0,B5/$B$7) -> 0.37853371
A6: Ultimate | B6: =SUMIFS('Base de Dados'!$P$2:$P$1201,'Base de Dados'!$C$2:$C$1201,A6) -> 380109.78 | C6: =IF($B$7=0,0,B6/$B$7) -> 0.32892089
A7: TOTAL | B7: =SUM(B4:B6) -> 1155626.8
A9: RECEITA POR REGIÃO
A10: Região | B10: Receita (R$) | C10: Participação
A11: Sudeste | B11: =SUMIFS('Base de Dados'!$P$2:$P$1201,'Base de Dados'!$E$2:$E$1201,A11) -> 472762.68 | C11: =IF($B$16=0,0,B11/$B$16) -> 0.40909634
A12: Sul | B12: =SUMIFS('Base de Dados'!$P$2:$P$1201,'Base de Dados'!$E$2:$E$1201,A12) -> 234011.96 | C12: =IF($B$16=0,0,B12/$B$16) -> 0.20249787
A13: Nordeste | B13: =SUMIFS('Base de Dados'!$P$2:$P$1201,'Base de Dados'!$E$2:$E$1201,A13) -> 253889.19 | C13: =IF($B$16=0,0,B13/$B$16) -> 0.21969826
A14: Centro-Oeste | B14: =SUMIFS('Base de Dados'!$P$2:$P$1201,'Base de Dados'!$E$2:$E$1201,A14) -> 109712.77 | C14: =IF($B$16=0,0,B14/$B$16) -> 0.094937893
A15: Norte | B15: =SUMIFS('Base de Dados'!$P$2:$P$1201,'Base de Dados'!$E$2:$E$1201,A15) -> 85250.181 | C15: =IF($B$16=0,0,B15/$B$16) -> 0.073769649
A16: TOTAL | B16: =SUM(B11:B15) -> 1155626.8
A18: RECEITA POR CICLO DE FATURAMENTO
A19: Ciclo | B19: Receita (R$) | C19: Participação
A20: Mensal | B20: =SUMIFS('Base de Dados'!$P$2:$P$1201,'Base de Dados'!$D$2:$D$1201,A20) -> 214498.13 | C20: =IF($B$23=0,0,B20/$B$23) -> 0.18561194
A21: Trimestral | B21: =SUMIFS('Base de Dados'!$P$2:$P$1201,'Base de Dados'!$D$2:$D$1201,A21) -> 296481.7 | C21: =IF($B$23=0,0,B21/$B$23) -> 0.25655489
A22: Anual | B22: =SUMIFS('Base de Dados'!$P$2:$P$1201,'Base de Dados'!$D$2:$D$1201,A22) -> 644646.95 | C22: =IF($B$23=0,0,B22/$B$23) -> 0.55783317
A23: TOTAL | B23: =SUM(B20:B22) -> 1155626.8
A25: RECEITA POR ADD-ON
A26: Add-on | B26: Receita (R$)
A27: EA Play | B27: =SUM('Base de Dados'!$M$2:$M$1201) -> 49680.44
A28: Minecraft Pass | B28: =SUM('Base de Dados'!$N$2:$N$1201) -> 34697.04
A29: Call of Duty Pass | B29: =SUM('Base de Dados'!$O$2:$O$1201) -> 41115.18
A31: NOVOS vs RENOVAÇÃO
A32: Tipo | B32: Receita (R$)
A33: Novo | B33: =SUMIFS('Base de Dados'!$P$2:$P$1201,'Base de Dados'!$J$2:$J$1201,"Novo") -> 613005.39
A34: Renovação | B34: =SUMIFS('Base de Dados'!$P$2:$P$1201,'Base de Dados'!$J$2:$J$1201,"Renovação") -> 542621.39
A36: EVOLUÇÃO MENSAL DA RECEITA
A37: Mês (início) | B37: Rótulo | C37: Receita (R$) | D37: Próx. mês
A38: 45292 | B38: =TEXT(A38,"mmm/yyyy") -> jan/yyyy | C38: =SUMIFS('Base de Dados'!$P$2:$P$1201,'Base de Dados'!$B$2:$B$1201,">="&A38,'Base de Dados'!$B$2:$B$1201,"<"&D38) -> 57551.519 | D38: 45323
A39: 45323 | B39: =TEXT(A39,"mmm/yyyy") -> fev/yyyy | C39: =SUMIFS('Base de Dados'!$P$2:$P$1201,'Base de Dados'!$B$2:$B$1201,">="&A39,'Base de Dados'!$B$2:$B$1201,"<"&D39) -> 28878.031 | D39: 45352
A40: 45352 | B40: =TEXT(A40,"mmm/yyyy") -> mar/yyyy | C40: =SUMIFS('Base de Dados'!$P$2:$P$1201,'Base de Dados'!$B$2:$B$1201,">="&A40,'Base de Dados'!$B$2:$B$1201,"<"&D40) -> 37705.861 | D40: 45383
A41: 45383 | B41: =TEXT(A41,"mmm/yyyy") -> abr/yyyy | C41: =SUMIFS('Base de Dados'!$P$2:$P$1201,'Base de Dados'!$B$2:$B$1201,">="&A41,'Base de Dados'!$B$2:$B$1201,"<"&D41) -> 52865.995 | D41: 45413
A42: 45413 | B42: =TEXT(A42,"mmm/yyyy") -> mai/yyyy | C42: =SUMIFS('Base de Dados'!$P$2:$P$1201,'Base de Dados'!$B$2:$B$1201,">="&A42,'Base de Dados'!$B$2:$B$1201,"<"&D42) -> 53363.609 | D42: 45444
A43: 45444 | B43: =TEXT(A43,"mmm/yyyy") -> jun/yyyy | C43: =SUMIFS('Base de Dados'!$P$2:$P$1201,'Base de Dados'!$B$2:$B$1201,">="&A43,'Base de Dados'!$B$2:$B$1201,"<"&D43) -> 36048.073 | D43: 45474
A44: 45474 | B44: =TEXT(A44,"mmm/yyyy") -> jul/yyyy | C44: =SUMIFS('Base de Dados'!$P$2:$P$1201,'Base de Dados'!$B$2:$B$1201,">="&A44,'Base de Dados'!$B$2:$B$1201,"<"&D44) -> 49747.693 | D44: 45505
A45: 45505 | B45: =TEXT(A45,"mmm/yyyy") -> ago/yyyy | C45: =SUMIFS('Base de Dados'!$P$2:$P$1201,'Base de Dados'!$B$2:$B$1201,">="&A45,'Base de Dados'!$B$2:$B$1201,"<"&D45) -> 51104.154 | D45: 45536
A46: 45536 | B46: =TEXT(A46,"mmm/yyyy") -> set/yyyy | C46: =SUMIFS('Base de Dados'!$P$2:$P$1201,'Base de Dados'!$B$2:$B$1201,">="&A46,'Base de Dados'!$B$2:$B$1201,"<"&D46) -> 53550.231 | D46: 45566
...

Sheet Dashboard
A1: XBOX GAME PASS — DASHBOARD DE VENDAS EXECUTIVO
A4: RECEITA TOTAL (R$) | E4: ASSINANTES (un.) | I4: LUCRO TOTAL (R$)
A5: =Cálculos!$B$7 -> 1155626.8 | E5: =SUM('Base de Dados'!$K$2:$K$1201) -> 21915 | I5: =SUM('Base de Dados'!$R$2:$R$1201) -> 892646.77
A7: ARPU (R$) | E7: TICKET MÉDIO (R$) | I7: MARGEM DE LUCRO
A8: =IF(SUM('Base de Dados'!$K$2:$K$1201)=0,0,Cálculos!$B$7/SUM('Base de Dados'!$K$2:$K$1201)) -> 52.732228 | E8: =IF(COUNT('Base de Dados'!$A$2:$A$1201)=0,0,Cálculos!$B$7/COUNT('Base de Dados'!$A$2:$A$1201)) -> 963.02231 | I8: =IF(Cálculos!$B$7=0,0,SUM('Base de Dados'!$R$2:$R$1201)/Cálculos!$B$7) -> 0.77243518
A10: Atingimento de Meta → Receita: =TEXT('Cálculos'!$B$7/Parâmetros!$B$17,"0%") | Assinantes: =TEXT(SUM('Base de Dados'!$K$2:$K$1201)/Parâmetros!$B$18,"0%") | Câmbio USD: =TEXT(Parâmetros!$B$24,"R$ 0.00")
A11: Visão Analítica (gráficos atualizam automaticamente ao alterar a aba Parâmetros):

Sheet Instruções
A1: INSTRUÇÕES DE USO — DASHBOARD XBOX GAME PASS
A3: 1. Aba 'Parâmetros' → É a ÚNICA aba que você precisa editar.
A4: • As células em AMARELO são editáveis (preços, metas, descontos, CAC, câmbio, etc.).
A5: • Qualquer alteração aqui recalcula TODA a base e o Dashboard automaticamente ao abrir no Excel.
A7: 2. Aba 'Base de Dados' → Registros de transações (artificiais/demo).
A8: • As colunas de Receita, Custo e Lucro usam fórmulas que puxam os preços da aba Parâmetros.
A9: • Não é necessário editar manualmente; serve como fonte para os gráficos.
A11: 3. Aba 'Cálculos' → Agregações (SUMIFS) por Plano, Região, Ciclo, Add-on, Novos/Renovação e Evolução Mensal.
A12: • Totalmente automática — não edite diretamente.
A14: 4. Aba 'Dashboard' → Cartões de KPI + 6 gráficos executivos.
A15: • KPIs: Receita Total, Assinantes, Lucro, ARPU, Ticket Médio, Margem, % de Meta atingida.
A16: • Use os filtros/segmentações no Excel para explorar; os gráficos reagem aos Parâmetros.
... A19: basta mudar os valores amarelos e观察 o impacto nos KPIs e gráficos.
